Workbook
Name PhaseList: tblPhases[Phase]
Name pjEnd: Projects!$F$5:$F$1188
Name pjFee: Projects!$H$5:$H$1188
Name pjName: Projects!$B$5:$B$1188
Name pjNo: Projects!$A$5:$A$1188
Name pjPhase: Projects!$C$5:$C$1188
Name pjStart: Projects!$E$5:$E$1188
Name pjStatus: Projects!$D$5:$D$1188
Name pjTotDir: Projects!$T$5:$T$1188
Name pjTotHrs: Projects!$P$5:$P$1188
Name pjTotMid: Projects!$V$5:$V$1188
Name pjTotPD: Projects!$W$5:$W$1188
Name pjTotPr: Projects!$S$5:$S$1188
Name pjTotSD: Projects!$U$5:$U$1188
Name pjType: Projects!$AC$5:$AC$1188
Name pjValue: Projects!$X$5:$X$1188
Name pjWeight: Projects!$AA$5:$AA$1188
Name pjWk: Projects!$AD$5:$AD$1188
Name StaffList: tblStaff[Initials]
Name tlLevel: Timeline!$BJ$20:$BJ$378
Name tlNo: Timeline!$A$20:$A$378
Name tlPhase: Timeline!$C$20:$C$378
Name tlPlaced: Timeline!$F$20:$F$378
Name tlPool: Timeline!$E$20:$E$378
Name tlSrc: Timeline!$BI$20:$BI$378
Name tlStaff: Timeline!$D$20:$D$378
Name tlWeight: Timeline!$BM$20:$BM$378

Sheet Dashboard
A1: Agency Artifact — Staffing & Capacity Dashboard
A2: ="Scenario: "&Assumptions!B6&" | Forecast: "&TEXT(Forecast!D5,"m/d/yy")&" – "&TEXT(Forecast!BC5+6,"m/d/yy")&" (52 weeks)" -> Scenario: Active + Prospective | Forecast: 10/5/26 – 10/3/27 (52 weeks)
A4: KEY METRICS
A5: Phases counted in scenario | B5: =COUNTIFS(pjWeight,">0",pjType,"<>Project") -> 43
A6: Peak firm utilization | B6: =Forecast!C85 -> 1.2033898 | C6: ="Week of "&TEXT(INDEX(Forecast!D5:BC5,MATCH(Forecast!C85,Forecast!D85:BC85,0)),"m/d/yy") -> Week of 10/26/26
A7: Average firm utilization | B7: =Forecast!B85 -> 0.30353651
A8: Weeks with any level understaffed | B8: =COUNTIF(Forecast!D96:BC96,">0") -> 17 | C8: of 52 weeks
A9: Weeks with any level in excess capacity | B9: =COUNTIF(Forecast!D97:BC97,">0") -> 46 | C9: of 52 weeks
A10: Total phase fees | B10: =Economics!F9 -> 2591500 | C10: All phases on Projects sheet
A11: Total projected cost of planned hours | B11: =Economics!E9 -> 1098015
A12: Fee vs projected cost | B12: =Economics!G9 -> 1493485 | C12: =IF(Economics!F9=0,"","Projected cost = "&TEXT(Economics!H9,"0%")&" of fee") -> Projected cost = 42% of fee
A14: STAFFING OUTLOOK — peak utilization and FTE shortfall by time horizon
B15: ="Near-term (wks 1–"&Assumptions!$K$5&")" -> Near-term (wks 1–12) | D15: ="Mid-term (wks "&(Assumptions!$K$5+1)&"–"&Assumptions!$K$6&")" -> Mid-term (wks 13–24) | F15: ="Long-range (wks "&(Assumptions!$K$6+1)&"–52)" -> Long-range (wks 25–52)
A16: Staff Level | B16: Peak Util. | C16: Peak FTE Short | D16: Peak Util. | E16: Peak FTE Short | F16: Peak Util. | G16: Peak FTE Short
A17: =Assumptions!A15 -> Principal | B17: =_xlfn.MAXIFS(Forecast!$D$80:$BC$80,Forecast!$D$4:$BC$4,">="&1,Forecast!$D$4:$BC$4,"<="&Assumptions!$K$5) -> 1.5833333 | C17: =MAX(0,_xlfn.MAXIFS(Forecast!$D$88:$BC$88,Forecast!$D$4:$BC$4,">="&1,Forecast!$D$4:$BC$4,"<="&Assumptions!$K$5)) -> 1.1666667 | D17: =_xlfn.MAXIFS(Forecast!$D$80:$BC$80,Forecast!$D$4:$BC$4,">="&Assumptions!$K$5+1,Forecast!$D$4:$BC$4,"<="&Assumptions!$K$6) -> 0.56666667 | E17: =MAX(0,_xlfn.MAXIFS(Forecast!$D$88:$BC$88,Forecast!$D$4:$BC$4,">="&Assumptions!$K$5+1,Forecast!$D$4:$BC$4,"<="&Assumptions!$K$6)) -> 0 | F17: =_xlfn.MAXIFS(Forecast!$D$80:$BC$80,Forecast!$D$4:$BC$4,">="&Assumptions!$K$6+1,Forecast!$D$4:$BC$4,"<="&52) -> 0.033333333 | G17: =MAX(0,_xlfn.MAXIFS(Forecast!$D$88:$BC$88,Forecast!$D$4:$BC$4,">="&Assumptions!$K$6+1,Forecast!$D$4:$BC$4,"<="&52)) -> 0
A18: =Assumptions!A16 -> Director | B18: =_xlfn.MAXIFS(Forecast!$D$81:$BC$81,Forecast!$D$4:$BC$4,">="&1,Forecast!$D$4:$BC$4,"<="&Assumptions!$K$5) -> 1.1875 | C18: =MAX(0,_xlfn.MAXIFS(Forecast!$D$89:$BC$89,Forecast!$D$4:$BC$4,">="&1,Forecast!$D$4:$BC$4,"<="&Assumptions!$K$5)) -> 0.1875 | D18: =_xlfn.MAXIFS(Forecast!$D$81:$BC$81,Forecast!$D$4:$BC$4,">="&Assumptions!$K$5+1,Forecast!$D$4:$BC$4,"<="&Assumptions!$K$6) -> 1.125 | E18: =MAX(0,_xlfn.MAXIFS(Forecast!$D$89:$BC$89,Forecast!$D$4:$BC$4,">="&Assumptions!$K$5+1,Forecast!$D$4:$BC$4,"<="&Assumptions!$K$6)) -> 0.125 | F18: =_xlfn.MAXIFS(Forecast!$D$81:$BC$81,Forecast!$D$4:$BC$4,">="&Assumptions!$K$6+1,Forecast!$D$4:$BC$4,"<="&52) -> 0.625 | G18: =MAX(0,_xlfn.MAXIFS(Forecast!$D$89:$BC$89,Forecast!$D$4:$BC$4,">="&Assumptions!$K$6+1,Forecast!$D$4:$BC$4,"<="&52)) -> 0
A19: =Assumptions!A17 -> Senior Designer | B19: =_xlfn.MAXIFS(Forecast!$D$82:$BC$82,Forecast!$D$4:$BC$4,">="&1,Forecast!$D$4:$BC$4,"<="&Assumptions!$K$5) -> 1.4444444 | C19: =MAX(0,_xlfn.MAXIFS(Forecast!$D$90:$BC$90,Forecast!$D$4:$BC$4,">="&1,Forecast!$D$4:$BC$4,"<="&Assumptions!$K$5)) -> 0.44444444 | D19: =_xlfn.MAXIFS(Forecast!$D$82:$BC$82,Forecast!$D$4:$BC$4,">="&Assumptions!$K$5+1,Forecast!$D$4:$BC$4,"<="&Assumptions!$K$6) -> 0.44444444 | E19: =MAX(0,_xlfn.MAXIFS(Forecast!$D$90:$BC$90,Forecast!$D$4:$BC$4,">="&Assumptions!$K$5+1,Forecast!$D$4:$BC$4,"<="&Assumptions!$K$6)) -> 0 | F19: =_xlfn.MAXIFS(Forecast!$D$82:$BC$82,Forecast!$D$4:$BC$4,">="&Assumptions!$K$6+1,Forecast!$D$4:$BC$4,"<="&52) -> 0 | G19: =MAX(0,_xlfn.MAXIFS(Forecast!$D$90:$BC$90,Forecast!$D$4:$BC$4,">="&Assumptions!$K$6+1,Forecast!$D$4:$BC$4,"<="&52)) -> 0
A20: =Assumptions!A18 -> Mid Level Designer | B20: =_xlfn.MAXIFS(Forecast!$D$83:$BC$83,Forecast!$D$4:$BC$4,">="&1,Forecast!$D$4:$BC$4,"<="&Assumptions!$K$5) -> 0.90277778 | C20: =MAX(0,_xlfn.MAXIFS(Forecast!$D$91:$BC$91,Forecast!$D$4:$BC$4,">="&1,Forecast!$D$4:$BC$4,"<="&Assumptions!$K$5)) -> 0 | D20: =_xlfn.MAXIFS(Forecast!$D$83:$BC$83,Forecast!$D$4:$BC$4,">="&Assumptions!$K$5+1,Forecast!$D$4:$BC$4,"<="&Assumptions!$K$6) -> 0.44444444 | E20: =MAX(0,_xlfn.MAXIFS(Forecast!$D$91:$BC$91,Forecast!$D$4:$BC$4,">="&Assumptions!$K$5+1,Forecast!$D$4:$BC$4,"<="&Assumptions!$K$6)) -> 0 | F20: =_xlfn.MAXIFS(Forecast!$D$83:$BC$83,Forecast!$D$4:$BC$4,">="&Assumptions!$K$6+1,Forecast!$D$4:$BC$4,"<="&52) -> 0.27777778 | G20: =MAX(0,_xlfn.MAXIFS(Forecast!$D$91:$BC$91,Forecast!$D$4:$BC$4,">="&Assumptions!$K$6+1,Forecast!$D$4:$BC$4,"<="&52)) -> 0
A21: =Assumptions!A19 -> Project Designer | B21: =_xlfn.MAXIFS(Forecast!$D$84:$BC$84,Forecast!$D$4:$BC$4,">="&1,Forecast!$D$4:$BC$4,"<="&Assumptions!$K$5) -> 1.5555556 | C21: =MAX(0,_xlfn.MAXIFS(Forecast!$D$92:$BC$92,Forecast!$D$4:$BC$4,">="&1,Forecast!$D$4:$BC$4,"<="&Assumptions!$K$5)) -> 0.55555556 | D21: =_xlfn.MAXIFS(Forecast!$D$84:$BC$84,Forecast!$D$4:$BC$4,">="&Assumptions!$K$5+1,Forecast!$D$4:$BC$4,"<="&Assumptions!$K$6) -> 1.6666667 | E21: =MAX(0,_xlfn.MAXIFS(Forecast!$D$92:$BC$92,Forecast!$D$4:$BC$4,">="&Assumptions!$K$5+1,Forecast!$D$4:$BC$4,"<="&Assumptions!$K$6)) -> 0.66666667 | F21: =_xlfn.MAXIFS(Forecast!$D$84:$BC$84,Forecast!$D$4:$BC$4,">="&Assumptions!$K$6+1,Forecast!$D$4:$BC$4,"<="&52) -> 0.11111111 | G21: =MAX(0,_xlfn.MAXIFS(Forecast!$D$92:$BC$92,Forecast!$D$4:$BC$4,">="&Assumptions!$K$6+1,Forecast!$D$4:$BC$4,"<="&52)) -> 0
A22: Firm total (net FTE) | B22: =_xlfn.MAXIFS(Forecast!$D$85:$BC$85,Forecast!$D$4:$BC$4,">="&1,Forecast!$D$4:$BC$4,"<="&Assumptions!$K$5) -> 1.2033898 | C22: =MAX(0,_xlfn.MAXIFS(Forecast!$D$93:$BC$93,Forecast!$D$4:$BC$4,">="&1,Forecast!$D$4:$BC$4,"<="&Assumptions!$K$5)) -> 1.5069444 | D22: =_xlfn.MAXIFS(Forecast!$D$85:$BC$85,Forecast!$D$4:$BC$4,">="&Assumptions!$K$5+1,Forecast!$D$4:$BC$4,"<="&Assumptions!$K$6) -> 0.72881356 | E22: =MAX(0,_xlfn.MAXIFS(Forecast!$D$93:$BC$93,Forecast!$D$4:$BC$4,">="&Assumptions!$K$5+1,Forecast!$D$4:$BC$4,"<="&Assumptions!$K$6)) -> 0 | F22: =_xlfn.MAXIFS(Forecast!$D$85:$BC$85,Forecast!$D$4:$BC$4,">="&Assumptions!$K$6+1,Forecast!$D$4:$BC$4,"<="&52) -> 0.19491525 | G22: =MAX(0,_xlfn.MAXIFS(Forecast!$D$93:$BC$93,Forecast!$D$4:$BC$4,">="&Assumptions!$K$6+1,Forecast!$D$4:$BC$4,"<="&52)) -> 0
A23: Red = understaffed / hire-level shortfall; amber = excess capacity or minor shortfall. Detail by week: Timeline (heat map + phase bars) and Forecast.
A24: HIRING SIGNALS BY STAFF LEVEL
A25: Staff Level | B25: Current FTE | C25: Peak Utilization | D25: Weeks Understaffed | E25: Weeks Excess Capacity | F25: Peak FTE Short | G25: First Hire-Trigger Week | H25: Hire-By Date | I25: Recommendation
A26: =Assumptions!A15 -> Principal | B26: =Assumptions!C15 -> 2 | C26: =Forecast!C80 -> 1.5833333 | D26: =COUNTIF(Forecast!D80:BC80,">"&Assumptions!$B$8) -> 6 | E26: =COUNTIF(Forecast!D80:BC80,"<"&Assumptions!$B$9) -> 41 | F26: =MAX(0,Forecast!C88) -> 1.1666667 | G26: {=IFERROR(INDEX(Forecast!$D$5:$BC$5,MATCH(TRUE,INDEX(Forecast!D88:BC88>=Assumptions!$B$10,0),0)),"None")} -> 46300 | H26: =IF(G26="None","—",G26-7*Assumptions!$B$11) -> 46244 | I26: =IF(G26="None",IF(D26>0,"Monitor — short-term overload, no sustained hire need","No hire needed"),"Hire "&ROUNDUP(F26,0)&" FTE — "&IF(H26<=Assumptions!$B$5,"start recruiting now","recruit by "&TEXT(H26,"m/d/yy"))) -> Hire 2 FTE — start recruiting now
A27: =Assumptions!A16 -> Director | B27: =Assumptions!C16 -> 1 | C27: =Forecast!C81 -> 1.1875 | D27: =COUNTIF(Forecast!D81:BC81,">"&Assumptions!$B$8) -> 3 | E27: =COUNTIF(Forecast!D81:BC81,"<"&Assumptions!$B$9) -> 35 | F27: =MAX(0,Forecast!C89) -> 0.1875 | G27: {=IFERROR(INDEX(Forecast!$D$5:$BC$5,MATCH(TRUE,INDEX(Forecast!D89:BC89>=Assumptions!$B$10,0),0)),"None")} -> None | H27: =IF(G27="None","—",G27-7*Assumptions!$B$11) -> — | I27: =IF(G27="None",IF(D27>0,"Monitor — short-term overload, no sustained hire need","No hire needed"),"Hire "&ROUNDUP(F27,0)&" FTE — "&IF(H27<=Assumptions!$B$5,"start recruiting now","recruit by "&TEXT(H27,"m/d/yy"))) -> Monitor — short-term overload, no sustained hire need
A28: =Assumptions!A17 -> Senior Designer | B28: =Assumptions!C17 -> 1 | C28: =Forecast!C82 -> 1.4444444 | D28: =COUNTIF(Forecast!D82:BC82,">"&Assumptions!$B$8) -> 6 | E28: =COUNTIF(Forecast!D82:BC82,"<"&Assumptions!$B$9) -> 45 | F28: =MAX(0,Forecast!C90) -> 0.44444444 | G28: {=IFERROR(INDEX(Forecast!$D$5:$BC$5,MATCH(TRUE,INDEX(Forecast!D90:BC90>=Assumptions!$B$10,0),0)),"None")} -> None | H28: =IF(G28="None","—",G28-7*Assumptions!$B$11) -> — | I28: =IF(G28="None",IF(D28>0,"Monitor — short-term overload, no sustained hire need","No hire needed"),"Hire "&ROUNDUP(F28,0)&" FTE — "&IF(H28<=Assumptions!$B$5,"start recruiting now","recruit by "&TEXT(H28,"m/d/yy"))) -> Monitor — short-term overload, no sustained hire need
A29: =Assumptions!A18 -> Mid Level Designer | B29: =Assumptions!C18 -> 2 | C29: =Forecast!C83 -> 0.90277778 | D29: =COUNTIF(Forecast!D83:BC83,">"&Assumptions!$B$8) -> 0 | E29: =COUNTIF(Forecast!D83:BC83,"<"&Assumptions!$B$9) -> 44 | F29: =MAX(0,Forecast!C91) -> 0 | G29: {=IFERROR(INDEX(Forecast!$D$5:$BC$5,MATCH(TRUE,INDEX(Forecast!D91:BC91>=Assumptions!$B$10,0),0)),"None")} -> None | H29: =IF(G29="None","—",G29-7*Assumptions!$B$11) -> — | I29: =IF(G29="None",IF(D29>0,"Monitor — short-term overload, no sustained hire need","No hire needed"),"Hire "&ROUNDUP(F29,0)&" FTE — "&IF(H29<=Assumptions!$B$5,"start recruiting now","recruit by "&TEXT(H29,"m/d/yy"))) -> No hire needed
A30: =Assumptions!A19 -> Project Designer | B30: =Assumptions!C19 -> 1 | C30: =Forecast!C84 -> 1.6666667 | D30: =COUNTIF(Forecast!D84:BC84,">"&Assumptions!$B$8) -> 17 | E30: =COUNTIF(Forecast!D84:BC84,"<"&Assumptions!$B$9) -> 35 | F30: =MAX(0,Forecast!C92) -> 0.66666667 | G30: {=IFERROR(INDEX(Forecast!$D$5:$BC$5,MATCH(TRUE,INDEX(Forecast!D92:BC92>=Assumptions!$B$10,0),0)),"None")} -> 46349 | H30: =IF(G30="None","—",G30-7*Assumptions!$B$11) -> 46293 | I30: =IF(G30="None",IF(D30>0,"Monitor — short-term overload, no sustained hire need","No hire needed"),"Hire "&ROUNDUP(F30,0)&" FTE — "&IF(H30<=Assumptions!$B$5,"start recruiting now","recruit by "&TEXT(H30,"m/d/yy"))) -> Hire 1 FTE — start recruiting now
A32: Hire-by date = first week FTE shortfall reaches the hire trigger minus hiring lead time (both set on Assumptions). Utilization is demand ÷ capacity (capacity already reflects target utilization).

Sheet Assumptions
A1: Agency Artifact — Staffing & Capacity Planner: Assumptions
A2: Blue cells are inputs. Change them here and every other sheet recalculates.
H3: Add custom phases in the first empty cell under the list — they appear in the Projects dropdown automatically.
A4: FORECAST SETTINGS | H4: PHASE / MILESTONE LIST | J4: TIMELINE HORIZONS
A5: Forecast start (must be a Monday) | B5: 46300 | C5: =IF(WEEKDAY(B5,2)=1,"OK — Monday","⚠ Not a Monday — change the date") -> OK — Monday | H5: Phase | J5: Near-term: through week # | K5: 12
A6: Scenario view | B6: Active + Prospective | C6: Active only = exclude prospective projects | H6: Concept | J6: Mid-term: through week # | K6: 24
A7: Prospective weighting | B7: 1 | C7: % of prospective hours counted in the forecast when included (e.g. 50% = probability-weight) | H7: Entitlement | J7: Long-range = mid-term end to week 52. Drives Timeline shading & Dashboard outlook.
A8: Understaffed flag: utilization above | B8: 1 | C8: Weekly demand ÷ capacity above this = understaffed (red) | H8: SD
A9: Overstaffed flag: utilization below | B9: 0.6 | C9: Weekly demand ÷ capacity below this = excess capacity (amber) | H9: DD | J9: STAFF ROSTER (drives headcount)
A10: Hire trigger: FTE shortfall ≥ | B10: 0.5 | C10: Shortfall (in FTEs) that counts as a hiring need | H10: CD | J10: Initials | K10: Staff Level | L10: FTE
A11: Hiring lead time (weeks) | B11: 8 | C11: Weeks needed to recruit and onboard; used for the hire-by date | H11: Bidding | J11: PK | K11: Principal | L11: 1
H12: Permitting | J12: DF | K12: Principal | L12: 1
A13: STAFF LEVELS & CAPACITY | H13: CA | J13: KJ | K13: Director | L13: 1
A14: Staff Level | B14: Billable Rate ($/hr) | C14: Headcount (FTE) | D14: Hours / FTE / Week | E14: Target Utilization | F14: Capacity (billable hrs/wk) | H14: Master Plan | J14: HL | K14: Senior Designer | L14: 1
A15: Principal | B15: 290 | C15: =SUMIFS(tblStaff[FTE],tblStaff[Staff Level],$A15) -> 2 | D15: 40 | E15: 0.75 | F15: =C15*D15*E15 -> 60 | H15: Phase 3- Choices | J15: EHH | K15: Mid Level Designer | L15: 1
A16: Director | B16: 250 | C16: =SUMIFS(tblStaff[FTE],tblStaff[Staff Level],$A16) -> 1 | D16: 40 | E16: 0.8 | F16: =C16*D16*E16 -> 32 | H16: Phase 4- Final Master Plan | J16: KD | K16: Mid Level Designer | L16: 1
A17: Senior Designer | B17: 200 | C17: =SUMIFS(tblStaff[FTE],tblStaff[Staff Level],$A17) -> 1 | D17: 40 | E17: 0.9 | F17: =C17*D17*E17 -> 36 | H17: Phase 5- Execution Plan | J17: XX | K17: Project Designer | L17: 1
A18: Mid Level Designer | B18: 175 | C18: =SUMIFS(tblStaff[FTE],tblStaff[Staff Level],$A18) -> 2 | D18: 40 | E18: 0.9 | F18: =C18*D18*E18 -> 72 | H18: ASR 1
A19: Project Designer | B19: 135 | C19: =SUMIFS(tblStaff[FTE],tblStaff[Staff Level],$A19) -> 1 | D19: 40 | E19: 0.9 | F19: =C19*D19*E19 -> 36 | H19: ASR 2 | J19: Edit this list for hires, departures or part-time staff (FTE 0.5). Headcount above updates.
A20: Total | C20: =SUM(C15:C19) -> 7 | F20: =SUM(F15:F19) -> 236 | H20: ASR 3
A21: Capacity = Headcount × Hours per FTE × Target Utilization. Use fractional FTEs for part-time staff or planned hires/departures.
A23: LISTS (drive dropdowns)
A24: Project Status | B24: Scenario View
A25: Active | B25: Active only
A26: Prospective | B26: Active + Prospective
A27: Inactive
A28: WEEKLY UPDATE CHECKLIST
A29: 1. Projects: for each project, fill the shaded header row (No., Name, Status), then one phase row per phase — pick phase, start/end dates, fee and weekly hours per level.
A30: 2. Check that each header row's Input Check reads 'All OK'. Change a single phase's Status to Prospective if only that phase is unconfirmed.
A31: 3. Assumptions: update headcount / utilization for hires, departures or leave.
A32: 4. Assumptions: to roll the calendar forward, change the forecast start to a new Monday.
A33: 5. Review Dashboard outlook & hiring signals, and the Timeline heat map.

Sheet Projects
A1: Project & Phase Planner — weekly input sheet | G1: Total Phase Fees (excl. inactive): | H1: =SUMIFS(pjFee,pjType,"<>Project",pjStatus,"<>Inactive") -> 2591500 | I1: STAFF HOURS PER WEEK × Weeks (col G) = hours pool
A2: Each project is a shaded header row with its phases underneath (click +/- at left to collapse). Phase rows: pick the phase, enter a Start Date and EITHER Weeks or an End Date, the phase fee, and each person's hours PER WEEK. Hours/week × Weeks = that person's pool, which you then map to actual weeks on the Timeline tab. Blue = input.
A3: PROJECT & PHASE INPUTS | I3: =IFERROR(INDEX(tblStaff[Staff Level],1),"") -> Principal | J3: =IFERROR(INDEX(tblStaff[Staff Level],2),"") -> Principal | K3: =IFERROR(INDEX(tblStaff[Staff Level],3),"") -> Director | L3: =IFERROR(INDEX(tblStaff[Staff Level],4),"") -> Senior Designer | M3: =IFERROR(INDEX(tblStaff[Staff Level],5),"") -> Mid Level Designer | N3: =IFERROR(INDEX(tblStaff[Staff Level],6),"") -> Mid Level Designer | O3: =IFERROR(INDEX(tblStaff[Staff Level],7),"") -> Project Designer | P3: CALCULATED — HOURS, MAPPING & ECONOMICS (do not overwrite)
A4: Project No. | B4: Project Name | C4: Phase / Milestone | D4: Status | E4: Start Date | F4: End Date | G4: Weeks | H4: Phase Fee ($) | I4: =IFERROR(INDEX(tblStaff[Initials],1),"") -> PK | J4: =IFERROR(INDEX(tblStaff[Initials],2),"") -> DF | K4: =IFERROR(INDEX(tblStaff[Initials],3),"") -> KJ | L4: =IFERROR(INDEX(tblStaff[Initials],4),"") -> HL | M4: =IFERROR(INDEX(tblStaff[Initials],5),"") -> EHH | N4: =IFERROR(INDEX(tblStaff[Initials],6),"") -> KD | O4: =IFERROR(INDEX(tblStaff[Initials],7),"") -> XX | P4: Total Hours Pool (hrs/wk × weeks) | Q4: Hours Mapped (Timeline) | R4: Left to Map | S4: =Assumptions!A15&" Pool Hrs" -> Principal Pool Hrs | T4: =Assumptions!A16&" Pool Hrs" -> Director Pool Hrs | U4: =Assumptions!A17&" Pool Hrs" -> Senior Designer Pool Hrs | V4: =Assumptions!A18&" Pool Hrs" -> Mid Level Designer Pool Hrs | W4: =Assumptions!A19&" Pool Hrs" -> Project Designer Pool Hrs | X4: Projected Cost ($) | Y4: Fee vs Cost ($) | Z4: % of Fee Used | AA4: Scenario Weight | AB4: Input Check | AC4: Row Type | AD4: Weeks (num)
A5: 2256 | B5: Marigold Promenade | C5: Project total | D5: Active | E5: =IF(COUNT(E6:E6)=0,"",MIN(E6:E6)) -> 46478 | F5: =IF(COUNT(F6:F6)=0,"",MAX(F6:F6)) -> 46665 | H5: =SUM(H6:H6) -> 43500 | P5: =SUM(P6:P6) -> 81 | Q5: =SUM(Q6:Q6) -> 80 | R5: =P5-Q5 -> 1 | S5: =SUM(S6:S6) -> 27 | T5: =SUM(T6:T6) -> 54 | U5: =SUM(U6:U6) -> 0 | V5: =SUM(V6:V6) -> 0 | W5: =SUM(W6:W6) -> 0 | X5: =SUM(X6:X6) -> 21330 | Y5: =H5-X5 -> 22170 | Z5: =IF(H5=0,"",X5/H5) -> 0.49034483 | AB5: =IF(COUNTIF(AB6:AB6,"?*")=0,"No phases yet",IF(COUNTIF(AB6:AB6,"OK")=COUNTIF(AB6:AB6,"?*"),"All OK",(COUNTIF(AB6:AB6,"?*")-COUNTIF(AB6:AB6,"OK"))&" to fix")) -> 1 to fix | AC5: Project | AD5: =IF(AC5="Phase",N(G5),0) -> 0
A6: =IF(A5="","",A5) -> 2256 | B6: =IF(B5="","",B5) -> Marigold Promenade | C6: CA | D6: =IF(COUNTA(C6,E6,H6,I6:O6)=0,"",IF(D5="","",D5)) -> Active | E6: 46478 | F6: 46665 | G6: =IF(OR(E6="",F6=""),"",IF(F6<E6,"",ROUNDUP((F6-E6+1)/7,0))) -> 27 | H6: 43500 | I6: 1 | K6: 2 | P6: =SUM(I6:O6)*N(G6) -> 81 | Q6: {=IF(OR(A6="",E6="",F6=""),0,SUMPRODUCT((tlNo=A6)*(Timeline!$H$18:$BG$18+6>=E6)*(Timeline!$H$18:$BG$18<=F6)*Timeline!$H$20:$BG$378))} -> 80 | R6: =P6-Q6 -> 1 | S6: =SUMIF($I$3:$O$3,Assumptions!$A$15,$I6:$O6)*N($G6) -> 27 | T6: =SUMIF($I$3:$O$3,Assumptions!$A$16,$I6:$O6)*N($G6) -> 54 | U6: =SUMIF($I$3:$O$3,Assumptions!$A$17,$I6:$O6)*N($G6) -> 0 | V6: =SUMIF($I$3:$O$3,Assumptions!$A$18,$I6:$O6)*N($G6) -> 0 | W6: =SUMIF($I$3:$O$3,Assumptions!$A$19,$I6:$O6)*N($G6) -> 0 | X6: =S6*Assumptions!$B$15+T6*Assumptions!$B$16+U6*Assumptions!$B$17+V6*Assumptions!$B$18+W6*Assumptions!$B$19 -> 21330 | Y6: =IF(D6="","",H6-X6) -> 22170 | Z6: =IF(OR(D6="",H6=0),"",X6/H6) -> 0.49034483 | AA6: =IF(D6="Active",1,IF(D6="Prospective",IF(Assumptions!$B$6="Active only",0,Assumptions!$B$7),0)) -> 1 | AB6: =IF(COUNTA(C6,E6,H6,I6:O6)=0,"",IF(C6="","Select phase",IF(OR(E6="",F6=""),"Enter dates",IF(F6<E6,"End before start",IF(H6="","Enter phase fee",IF(P6=0,"Enter staff hours",IF(R6<0,"Over-mapped on Timeline",IF(R6>0,"Map hours on Timeline","OK")))))))) -> Map hours on Timeline | AC6: Phase | AD6: =IF(AC6="Phase",N(G6),0) -> 27
A7: 2348 | B7: Fairhaven Senior Housing | C7: Project total | D7: Inactive | E7: =IF(COUNT(E8:E15)=0,"",MIN(E8:E15)) | F7: =IF(COUNT(F8:F15)=0,"",MAX(F8:F15)) | H7: =SUM(H8:H15) -> 0 | P7: =SUM(P8:P15) -> 0 | Q7: =SUM(Q8:Q15) -> 0 | R7: =P7-Q7 -> 0 | S7: =SUM(S8:S15) -> 0 | T7: =SUM(T8:T15) -> 0 | U7: =SUM(U8:U15) -> 0 | V7: =SUM(V8:V15) -> 0 | W7: =SUM(W8:W15) -> 0 | X7: =SUM(X8:X15) -> 0 | Y7: =H7-X7 -> 0 | Z7: =IF(H7=0,"",X7/H7) | AB7: =IF(COUNTIF(AB8:AB15,"?*")=0,"No phases yet",IF(COUNTIF(AB8:AB15,"OK")=COUNTIF(AB8:AB15,"?*"),"All OK",(COUNTIF(AB8:AB15,"?*")-COUNTIF(AB8:AB15,"OK"))&" to fix")) -> No phases yet | AC7: Project | AD7: =IF(AC7="Phase",N(G7),0) -> 0
A8: =IF(A7="","",A7) -> 2348 | B8: =IF(B7="","",B7) -> Fairhaven Senior Housing | D8: =IF(COUNTA(C8,E8,H8,I8:O8)=0,"",IF(D7="","",D7)) | F8: =IF(_xlfn.ISFORMULA(G8),"",IF(AND(E8<>"",N(G8)>0),E8+7*G8-1,"")) | G8: =IF(OR(E8="",F8=""),"",IF(F8<E8,"",ROUNDUP((F8-E8+1)/7,0))) | P8: =SUM(I8:O8)*N(G8) -> 0 | Q8: {=IF(OR(A8="",E8="",F8=""),0,SUMPRODUCT((tlNo=A8)*(Timeline!$H$18:$BG$18+6>=E8)*(Timeline!$H$18:$BG$18<=F8)*Timeline!$H$20:$BG$378))} -> 0 | R8: =P8-Q8 -> 0 | S8: =SUMIF($I$3:$O$3,Assumptions!$A$15,$I8:$O8)*N($G8) -> 0 | T8: =SUMIF($I$3:$O$3,Assumptions!$A$16,$I8:$O8)*N($G8) -> 0 | U8: =SUMIF($I$3:$O$3,Assumptions!$A$17,$I8:$O8)*N($G8) -> 0 | V8: =SUMIF($I$3:$O$3,Assumptions!$A$18,$I8:$O8)*N($G8) -> 0 | W8: =SUMIF($I$3:$O$3,Assumptions!$A$19,$I8:$O8)*N($G8) -> 0 | X8: =S8*Assumptions!$B$15+T8*Assumptions!$B$16+U8*Assumptions!$B$17+V8*Assumptions!$B$18+W8*Assumptions!$B$19 -> 0 | Y8: =IF(D8="","",H8-X8) | Z8: =IF(OR(D8="",H8=0),"",X8/H8) | AA8: =IF(D8="Active",1,IF(D8="Prospective",IF(Assumptions!$B$6="Active only",0,Assumptions!$B$7),0)) -> 0 | AB8: =IF(COUNTA(C8,E8,H8,I8:O8)=0,"",IF(C8="","Select phase",IF(OR(E8="",F8=""),"Enter dates",IF(F8<E8,"End before start",IF(H8="","Enter phase fee",IF(P8=0,"Enter staff hours",IF(R8<0,"Over-mapped on Timeline",IF(R8>0,"Map hours on Timeline","OK")))))))) | AC8: Phase | AD8: =IF(AC8="Phase",N(G8),0) -> 0
A9: =IF(A7="","",A7) -> 2348 | B9: =IF(B7="","",B7) -> Fairhaven Senior Housing | D9: =IF(COUNTA(C9,E9,H9,I9:O9)=0,"",IF(D7="","",D7)) | F9: =IF(_xlfn.ISFORMULA(G9),"",IF(AND(E9<>"",N(G9)>0),E9+7*G9-1,"")) | G9: =IF(OR(E9="",F9=""),"",IF(F9<E9,"",ROUNDUP((F9-E9+1)/7,0))) | P9: =SUM(I9:O9)*N(G9) -> 0 | Q9: {=IF(OR(A9="",E9="",F9=""),0,SUMPRODUCT((tlNo=A9)*(Timeline!$H$18:$BG$18+6>=E9)*(Timeline!$H$18:$BG$18<=F9)*Timeline!$H$20:$BG$378))} -> 0 | R9: =P9-Q9 -> 0 | S9: =SUMIF($I$3:$O$3,Assumptions!$A$15,$I9:$O9)*N($G9) -> 0 | T9: =SUMIF($I$3:$O$3,Assumptions!$A$16,$I9:$O9)*N($G9) -> 0 | U9: =SUMIF($I$3:$O$3,Assumptions!$A$17,$I9:$O9)*N($G9) -> 0 | V9: =SUMIF($I$3:$O$3,Assumptions!$A$18,$I9:$O9)*N($G9) -> 0 | W9: =SUMIF($I$3:$O$3,Assumptions!$A$19,$I9:$O9)*N($G9) -> 0 | X9: =S9*Assumptions!$B$15+T9*Assumptions!$B$16+U9*Assumptions!$B$17+V9*Assumptions!$B$18+W9*Assumptions!$B$19 -> 0 | Y9: =IF(D9="","",H9-X9) | Z9: =IF(OR(D9="",H9=0),"",X9/H9) | AA9: =IF(D9="Active",1,IF(D9="Prospective",IF(Assumptions!$B$6="Active only",0,Assumptions!$B$7),0)) -> 0 | AB9: =IF(COUNTA(C9,E9,H9,I9:O9)=0,"",IF(C9="","Select phase",IF(OR(E9="",F9=""),"Enter dates",IF(F9<E9,"End before start",IF(H9="","Enter phase fee",IF(P9=0,"Enter staff hours",IF(R9<0,"Over-mapped on Timeline",IF(R9>0,"Map hours on Timeline","OK")))))))) | AC9: Phase | AD9: =IF(AC9="Phase",N(G9),0) -> 0
A10: =IF(A7="","",A7) -> 2348 | B10: =IF(B7="","",B7) -> Fairhaven Senior Housing | D10: =IF(COUNTA(C10,E10,H10,I10:O10)=0,"",IF(D7="","",D7)) | F10: =IF(_xlfn.ISFORMULA(G10),"",IF(AND(E10<>"",N(G10)>0),E10+7*G10-1,"")) | G10: =IF(OR(E10="",F10=""),"",IF(F10<E10,"",ROUNDUP((F10-E10+1)/7,0))) | P10: =SUM(I10:O10)*N(G10) -> 0 | Q10: {=IF(OR(A10="",E10="",F10=""),0,SUMPRODUCT((tlNo=A10)*(Timeline!$H$18:$BG$18+6>=E10)*(Timeline!$H$18:$BG$18<=F10)*Timeline!$H$20:$BG$378))} -> 0 | R10: =P10-Q10 -> 0 | S10: =SUMIF($I$3:$O$3,Assumptions!$A$15,$I10:$O10)*N($G10) -> 0 | T10: =SUMIF($I$3:$O$3,Assumptions!$A$16,$I10:$O10)*N($G10) -> 0 | U10: =SUMIF($I$3:$O$3,Assumptions!$A$17,$I10:$O10)*N($G10) -> 0 | V10: =SUMIF($I$3:$O$3,Assumptions!$A$18,$I10:$O10)*N($G10) -> 0 | W10: =SUMIF($I$3:$O$3,Assumptions!$A$19,$I10:$O10)*N($G10) -> 0 | X10: =S10*Assumptions!$B$15+T10*Assumptions!$B$16+U10*Assumptions!$B$17+V10*Assumptions!$B$18+W10*Assumptions!$B$19 -> 0 | Y10: =IF(D10="","",H10-X10) | Z10: =IF(OR(D10="",H10=0),"",X10/H10) | AA10: =IF(D10="Active",1,IF(D10="Prospective",IF(Assumptions!$B$6="Active only",0,Assumptions!$B$7),0)) -> 0 | AB10: =IF(COUNTA(C10,E10,H10,I10:O10)=0,"",IF(C10="","Select phase",IF(OR(E10="",F10=""),"Enter dates",IF(F10<E10,"End before start",IF(H10="","Enter phase fee",IF(P10=0,"Enter staff hours",IF(R10<0,"Over-mapped on Timeline",IF(R10>0,"Map hours on Timeline","OK")))))))) | AC10: Phase | AD10: =IF(AC10="Phase",N(G10),0) -> 0
A11: =IF(A7="","",A7) -> 2348 | B11: =IF(B7="","",B7) -> Fairhaven Senior Housing | D11: =IF(COUNTA(C11,E11,H11,I11:O11)=0,"",IF(D7="","",D7)) | F11: =IF(_xlfn.ISFORMULA(G11),"",IF(AND(E11<>"",N(G11)>0),E11+7*G11-1,"")) | G11: =IF(OR(E11="",F11=""),"",IF(F11<E11,"",ROUNDUP((F11-E11+1)/7,0))) | P11: =SUM(I11:O11)*N(G11) -> 0 | Q11: {=IF(OR(A11="",E11="",F11=""),0,SUMPRODUCT((tlNo=A11)*(Timeline!$H$18:$BG$18+6>=E11)*(Timeline!$H$18:$BG$18<=F11)*Timeline!$H$20:$BG$378))} -> 0 | R11: =P11-Q11 -> 0 | S11: =SUMIF($I$3:$O$3,Assumptions!$A$15,$I11:$O11)*N($G11) -> 0 | T11: =SUMIF($I$3:$O$3,Assumptions!$A$16,$I11:$O11)*N($G11) -> 0 | U11: =SUMIF($I$3:$O$3,Assumptions!$A$17,$I11:$O11)*N($G11) -> 0 | V11: =SUMIF($I$3:$O$3,Assumptions!$A$18,$I11:$O11)*N($G11) -> 0 | W11: =SUMIF($I$3:$O$3,Assumptions!$A$19,$I11:$O11)*N($G11) -> 0 | X11: =S11*Assumptions!$B$15+T11*Assumptions!$B$16+U11*Assumptions!$B$17+V11*Assumptions!$B$18+W11*Assumptions!$B$19 -> 0 | Y11: =IF(D11="","",H11-X11) | Z11: =IF(OR(D11="",H11=0),"",X11/H11) | AA11: =IF(D11="Active",1,IF(D11="Prospective",IF(Assumptions!$B$6="Active only",0,Assumptions!$B$7),0)) -> 0 | AB11: =IF(COUNTA(C11,E11,H11,I11:O11)=0,"",IF(C11="","Select phase",IF(OR(E11="",F11=""),"Enter dates",IF(F11<E11,"End before start",IF(H11="","Enter phase fee",IF(P11=0,"Enter staff hours",IF(R11<0,"Over-mapped on Timeline",IF(R11>0,"Map hours on Timeline","OK")))))))) | AC11: Phase | AD11: =IF(AC11="Phase",N(G11),0) -> 0
A12: =IF(A7="","",A7) -> 2348 | B12: =IF(B7="","",B7) -> Fairhaven Senior Housing | D12: =IF(COUNTA(C12,E12,H12,I12:O12)=0,"",IF(D7="","",D7)) | F12: =IF(_xlfn.ISFORMULA(G12),"",IF(AND(E12<>"",N(G12)>0),E12+7*G12-1,"")) | G12: =IF(OR(E12="",F12=""),"",IF(F12<E12,"",ROUNDUP((F12-E12+1)/7,0))) | P12: =SUM(I12:O12)*N(G12) -> 0 | Q12: {=IF(OR(A12="",E12="",F12=""),0,SUMPRODUCT((tlNo=A12)*(Timeline!$H$18:$BG$18+6>=E12)*(Timeline!$H$18:$BG$18<=F12)*Timeline!$H$20:$BG$378))} -> 0 | R12: =P12-Q12 -> 0 | S12: =SUMIF($I$3:$O$3,Assumptions!$A$15,$I12:$O12)*N($G12) -> 0 | T12: =SUMIF($I$3:$O$3,Assumptions!$A$16,$I12:$O12)*N($G12) -> 0 | U12: =SUMIF($I$3:$O$3,Assumptions!$A$17,$I12:$O12)*N($G12) -> 0 | V12: =SUMIF($I$3:$O$3,Assumptions!$A$18,$I12:$O12)*N($G12) -> 0 | W12: =SUMIF($I$3:$O$3,Assumptions!$A$19,$I12:$O12)*N($G12) -> 0 | X12: =S12*Assumptions!$B$15+T12*Assumptions!$B$16+U12*Assumptions!$B$17+V12*Assumptions!$B$18+W12*Assumptions!$B$19 -> 0 | Y12: =IF(D12="","",H12-X12) | Z12: =IF(OR(D12="",H12=0),"",X12/H12) | AA12: =IF(D12="Active",1,IF(D12="Prospective",IF(Assumptions!$B$6="Active only",0,Assumptions!$B$7),0)) -> 0 | AB12: =IF(COUNTA(C12,E12,H12,I12:O12)=0,"",IF(C12="","Select phase",IF(OR(E12="",F12=""),"Enter dates",IF(F12<E12,"End before start",IF(H12="","Enter phase fee",IF(P12=0,"Enter staff hours",IF(R12<0,"Over-mapped on Timeline",IF(R12>0,"Map hours on Timeline","OK")))))))) | AC12: Phase | AD12: =IF(AC12="Phase",N(G12),0) -> 0
A13: =IF(A7="","",A7) -> 2348 | B13: =IF(B7="","",B7) -> Fairhaven Senior Housing | D13: =IF(COUNTA(C13,E13,H13,I13:O13)=0,"",IF(D7="","",D7)) | F13: =IF(_xlfn.ISFORMULA(G13),"",IF(AND(E13<>"",N(G13)>0),E13+7*G13-1,"")) | G13: =IF(OR(E13="",F13=""),"",IF(F13<E13,"",ROUNDUP((F13-E13+1)/7,0))) | P13: =SUM(I13:O13)*N(G13) -> 0 | Q13: {=IF(OR(A13="",E13="",F13=""),0,SUMPRODUCT((tlNo=A13)*(Timeline!$H$18:$BG$18+6>=E13)*(Timeline!$H$18:$BG$18<=F13)*Timeline!$H$20:$BG$378))} -> 0 | R13: =P13-Q13 -> 0 | S13: =SUMIF($I$3:$O$3,Assumptions!$A$15,$I13:$O13)*N($G13) -> 0 | T13: =SUMIF($I$3:$O$3,Assumptions!$A$16,$I13:$O13)*N($G13) -> 0 | U13: =SUMIF($I$3:$O$3,Assumptions!$A$17,$I13:$O13)*N($G13) -> 0 | V13: =SUMIF($I$3:$O$3,Assumptions!$A$18,$I13:$O13)*N($G13) -> 0 | W13: =SUMIF($I$3:$O$3,Assumptions!$A$19,$I13:$O13)*N($G13) -> 0 | X13: =S13*Assumptions!$B$15+T13*Assumptions!$B$16+U13*Assumptions!$B$17+V13*Assumptions!$B$18+W13*Assumptions!$B$19 -> 0 | Y13: =IF(D13="","",H13-X13) | Z13: =IF(OR(D13="",H13=0),"",X13/H13) | AA13: =IF(D13="Active",1,IF(D13="Prospective",IF(Assumptions!$B$6="Active only",0,Assumptions!$B$7),0)) -> 0 | AB13: =IF(COUNTA(C13,E13,H13,I13:O13)=0,"",IF(C13="","Select phase",IF(OR(E13="",F13=""),"Enter dates",IF(F13<E13,"End before start",IF(H13="","Enter phase fee",IF(P13=0,"Enter staff hours",IF(R13<0,"Over-mapped on Timeline",IF(R13>0,"Map hours on Timeline","OK")))))))) | AC13: Phase | AD13: =IF(AC13="Phase",N(G13),0) -> 0
A14: =IF(A7="","",A7) -> 2348 | B14: =IF(B7="","",B7) -> Fairhaven Senior Housing | D14: =IF(COUNTA(C14,E14,H14,I14:O14)=0,"",IF(D7="","",D7)) | F14: =IF(_xlfn.ISFORMULA(G14),"",IF(AND(E14<>"",N(G14)>0),E14+7*G14-1,"")) | G14: =IF(OR(E14="",F14=""),"",IF(F14<E14,"",ROUNDUP((F14-E14+1)/7,0))) | P14: =SUM(I14:O14)*N(G14) -> 0 | Q14: {=IF(OR(A14="",E14="",F14=""),0,SUMPRODUCT((tlNo=A14)*(Timeline!$H$18:$BG$18+6>=E14)*(Timeline!$H$18:$BG$18<=F14)*Timeline!$H$20:$BG$378))} -> 0 | R14: =P14-Q14 -> 0 | S14: =SUMIF($I$3:$O$3,Assumptions!$A$15,$I14:$O14)*N($G14) -> 0 | T14: =SUMIF($I$3:$O$3,Assumptions!$A$16,$I14:$O14)*N($G14) -> 0 | U14: =SUMIF($I$3:$O$3,Assumptions!$A$17,$I14:$O14)*N($G14) -> 0 | V14: =SUMIF($I$3:$O$3,Assumptions!$A$18,$I14:$O14)*N($G14) -> 0 | W14: =SUMIF($I$3:$O$3,Assumptions!$A$19,$I14:$O14)*N($G14) -> 0 | X14: =S14*Assumptions!$B$15+T14*Assumptions!$B$16+U14*Assumptions!$B$17+V14*Assumptions!$B$18+W14*Assumptions!$B$19 -> 0 | Y14: =IF(D14="","",H14-X14) | Z14: =IF(OR(D14="",H14=0),"",X14/H14) | AA14: =IF(D14="Active",1,IF(D14="Prospective",IF(Assumptions!$B$6="Active only",0,Assumptions!$B$7),0)) -> 0 | AB14: =IF(COUNTA(C14,E14,H14,I14:O14)=0,"",IF(C14="","Select phase",IF(OR(E14="",F14=""),"Enter dates",IF(F14<E14,"End before start",IF(H14="","Enter phase fee",IF(P14=0,"Enter staff hours",IF(R14<0,"Over-mapped on Timeline",IF(R14>0,"Map hours on Timeline","OK")))))))) | AC14: Phase | AD14: =IF(AC14="Phase",N(G14),0) -> 0
A15: =IF(A7="","",A7) -> 2348 | B15: =IF(B7="","",B7) -> Fairhaven Senior Housing | D15: =IF(COUNTA(C15,E15,H15,I15:O15)=0,"",IF(D7="","",D7)) | F15: =IF(_xlfn.ISFORMULA(G15),"",IF(AND(E15<>"",N(G15)>0),E15+7*G15-1,"")) | G15: =IF(OR(E15="",F15=""),"",IF(F15<E15,"",ROUNDUP((F15-E15+1)/7,0))) | P15: =SUM(I15:O15)*N(G15) -> 0 | Q15: {=IF(OR(A15="",E15="",F15=""),0,SUMPRODUCT((tlNo=A15)*(Timeline!$H$18:$BG$18+6>=E15)*(Timeline!$H$18:$BG$18<=F15)*Timeline!$H$20:$BG$378))} -> 0 | R15: =P15-Q15 -> 0 | S15: =SUMIF($I$3:$O$3,Assumptions!$A$15,$I15:$O15)*N($G15) -> 0 | T15: =SUMIF($I$3:$O$3,Assumptions!$A$16,$I15:$O15)*N($G15) -> 0 | U15: =SUMIF($I$3:$O$3,Assumptions!$A$17,$I15:$O15)*N($G15) -> 0 | V15: =SUMIF($I$3:$O$3,Assumptions!$A$18,$I15:$O15)*N($G15) -> 0 | W15: =SUMIF($I$3:$O$3,Assumptions!$A$19,$I15:$O15)*N($G15) -> 0 | X15: =S15*Assumptions!$B$15+T15*Assumptions!$B$16+U15*Assumptions!$B$17+V15*Assumptions!$B$18+W15*Assumptions!$B$19 -> 0 | Y15: =IF(D15="","",H15-X15) | Z15: =IF(OR(D15="",H15=0),"",X15/H15) | AA15: =IF(D15="Active",1,IF(D15="Prospective",IF(Assumptions!$B$6="Active only",0,Assumptions!$B$7),0)) -> 0 | AB15: =IF(COUNTA(C15,E15,H15,I15:O15)=0,"",IF(C15="","Select phase",IF(OR(E15="",F15=""),"Enter dates",IF(F15<E15,"End before start",IF(H15="","Enter phase fee",IF(P15=0,"Enter staff hours",IF(R15<0,"Over-mapped on Timeline",IF(R15>0,"Map hours on Timeline","OK")))))))) | AC15: Phase | AD15: =IF(AC15="Phase",N(G15),0) -> 0
A16: 2370 | B16: Tamarack Housing | C16: Project total | D16: Inactive | E16: =IF(COUNT(E17:E24)=0,"",MIN(E17:E24)) | F16: =IF(COUNT(F17:F24)=0,"",MAX(F17:F24)) | H16: =SUM(H17:H24) -> 0 | P16: =SUM(P17:P24) -> 0 | Q16: =SUM(Q17:Q24) -> 0 | R16: =P16-Q16 -> 0 | S16: =SUM(S17:S24) -> 0 | T16: =SUM(T17:T24) -> 0 | U16: =SUM(U17:U24) -> 0 | V16: =SUM(V17:V24) -> 0 | W16: =SUM(W17:W24) -> 0 | X16: =SUM(X17:X24) -> 0 | Y16: =H16-X16 -> 0 | Z16: =IF(H16=0,"",X16/H16) | AB16: =IF(COUNTIF(AB17:AB24,"?*")=0,"No phases yet",IF(COUNTIF(AB17:AB24,"OK")=COUNTIF(AB17:AB24,"?*"),"All OK",(COUNTIF(AB17:AB24,"?*")-COUNTIF(AB17:AB24,"OK"))&" to fix")) -> No phases yet | AC16: Project | AD16: =IF(AC16="Phase",N(G16),0) -> 0
A17: =IF(A16="","",A16) -> 2370 | B17: =IF(B16="","",B16) -> Tamarack Housing | D17: =IF(COUNTA(C17,E17,H17,I17:O17)=0,"",IF(D16="","",D16)) | F17: =IF(_xlfn.ISFORMULA(G17),"",IF(AND(E17<>"",N(G17)>0),E17+7*G17-1,"")) | G17: =IF(OR(E17="",F17=""),"",IF(F17<E17,"",ROUNDUP((F17-E17+1)/7,0))) | P17: =SUM(I17:O17)*N(G17) -> 0 | Q17: {=IF(OR(A17="",E17="",F17=""),0,SUMPRODUCT((tlNo=A17)*(Timeline!$H$18:$BG$18+6>=E17)*(Timeline!$H$18:$BG$18<=F17)*Timeline!$H$20:$BG$378))} -> 0 | R17: =P17-Q17 -> 0 | S17: =SUMIF($I$3:$O$3,Assumptions!$A$15,$I17:$O17)*N($G17) -> 0 | T17: =SUMIF($I$3:$O$3,Assumptions!$A$16,$I17:$O17)*N($G17) -> 0 | U17: =SUMIF($I$3:$O$3,Assumptions!$A$17,$I17:$O17)*N($G17) -> 0 | V17: =SUMIF($I$3:$O$3,Assumptions!$A$18,$I17:$O17)*N($G17) -> 0 | W17: =SUMIF($I$3:$O$3,Assumptions!$A$19,$I17:$O17)*N($G17) -> 0 | X17: =S17*Assumptions!$B$15+T17*Assumptions!$B$16+U17*Assumptions!$B$17+V17*Assumptions!$B$18+W17*Assumptions!$B$19 -> 0 | Y17: =IF(D17="","",H17-X17) | Z17: =IF(OR(D17="",H17=0),"",X17/H17) | AA17: =IF(D17="Active",1,IF(D17="Prospective",IF(Assumptions!$B$6="Active only",0,Assumptions!$B$7),0)) -> 0 | AB17: =IF(COUNTA(C17,E17,H17,I17:O17)=0,"",IF(C17="","Select phase",IF(OR(E17="",F17=""),"Enter dates",IF(F17<E17,"End before start",IF(H17="","Enter phase fee",IF(P17=0,"Enter staff hours",IF(R17<0,"Over-mapped on Timeline",IF(R17>0,"Map hours on Timeline","OK")))))))) | AC17: Phase | AD17: =IF(AC17="Phase",N(G17),0) -> 0
A18: =IF(A16="","",A16) -> 2370 | B18: =IF(B16="","",B16) -> Tamarack Housing | D18: =IF(COUNTA(C18,E18,H18,I18:O18)=0,"",IF(D16="","",D16)) | F18: =IF(_xlfn.ISFORMULA(G18),"",IF(AND(E18<>"",N(G18)>0),E18+7*G18-1,"")) | G18: =IF(OR(E18="",F18=""),"",IF(F18<E18,"",ROUNDUP((F18-E18+1)/7,0))) | P18: =SUM(I18:O18)*N(G18) -> 0 | Q18: {=IF(OR(A18="",E18="",F18=""),0,SUMPRODUCT((tlNo=A18)*(Timeline!$H$18:$BG$18+6>=E18)*(Timeline!$H$18:$BG$18<=F18)*Timeline!$H$20:$BG$378))} -> 0 | R18: =P18-Q18 -> 0 | S18: =SUMIF($I$3:$O$3,Assumptions!$A$15,$I18:$O18)*N($G18) -> 0 | T18: =SUMIF($I$3:$O$3,Assumptions!$A$16,$I18:$O18)*N($G18) -> 0 | U18: =SUMIF($I$3:$O$3,Assumptions!$A$17,$I18:$O18)*N($G18) -> 0 | V18: =SUMIF($I$3:$O$3,Assumptions!$A$18,$I18:$O18)*N($G18) -> 0 | W18: =SUMIF($I$3:$O$3,Assumptions!$A$19,$I18:$O18)*N($G18) -> 0 | X18: =S18*Assumptions!$B$15+T18*Assumptions!$B$16+U18*Assumptions!$B$17+V18*Assumptions!$B$18+W18*Assumptions!$B$19 -> 0 | Y18: =IF(D18="","",H18-X18) | Z18: =IF(OR(D18="",H18=0),"",X18/H18) | AA18: =IF(D18="Active",1,IF(D18="Prospective",IF(Assumptions!$B$6="Active only",0,Assumptions!$B$7),0)) -> 0 | AB18: =IF(COUNTA(C18,E18,H18,I18:O18)=0,"",IF(C18="","Select phase",IF(OR(E18="",F18=""),"Enter dates",IF(F18<E18,"End before start",IF(H18="","Enter phase fee",IF(P18=0,"Enter staff hours",IF(R18<0,"Over-mapped on Timeline",IF(R18>0,"Map hours on Timeline","OK")))))))) | AC18: Phase | AD18: =IF(AC18="Phase",N(G18),0) -> 0
A19: =IF(A16="","",A16) -> 2370 | B19: =IF(B16="","",B16) -> Tamarack Housing | D19: =IF(COUNTA(C19,E19,H19,I19:O19)=0,"",IF(D16="","",D16)) | F19: =IF(_xlfn.ISFORMULA(G19),"",IF(AND(E19<>"",N(G19)>0),E19+7*G19-1,"")) | G19: =IF(OR(E19="",F19=""),"",IF(F19<E19,"",ROUNDUP((F19-E19+1)/7,0))) | P19: =SUM(I19:O19)*N(G19) -> 0 | Q19: {=IF(OR(A19="",E19="",F19=""),0,SUMPRODUCT((tlNo=A19)*(Timeline!$H$18:$BG$18+6>=E19)*(Timeline!$H$18:$BG$18<=F19)*Timeline!$H$20:$BG$378))} -> 0 | R19: =P19-Q19 -> 0 | S19: =SUMIF($I$3:$O$3,Assumptions!$A$15,$I19:$O19)*N($G19) -> 0 | T19: =SUMIF($I$3:$O$3,Assumptions!$A$16,$I19:$O19)*N($G19) -> 0 | U19: =SUMIF($I$3:$O$3,Assumptions!$A$17,$I19:$O19)*N($G19) -> 0 | V19: =SUMIF($I$3:$O$3,Assumptions!$A$18,$I19:$O19)*N($G19) -> 0 | W19: =SUMIF($I$3:$O$3,Assumptions!$A$19,$I19:$O19)*N($G19) -> 0 | X19: =S19*Assumptions!$B$15+T19*Assumptions!$B$16+U19*Assumptions!$B$17+V19*Assumptions!$B$18+W19*Assumptions!$B$19 -> 0 | Y19: =IF(D19="","",H19-X19) | Z19: =IF(OR(D19="",H19=0),"",X19/H19) | AA19: =IF(D19="Active",1,IF(D19="Prospective",IF(Assumptions!$B$6="Active only",0,Assumptions!$B$7),0)) -> 0 | AB19: =IF(COUNTA(C19,E19,H19,I19:O19)=0,"",IF(C19="","Select phase",IF(OR(E19="",F19=""),"Enter dates",IF(F19<E19,"End before start",IF(H19="","Enter phase fee",IF(P19=0,"Enter staff hours",IF(R19<0,"Over-mapped on Timeline",IF(R19>0,"Map hours on Timeline","OK")))))))) | AC19: Phase | AD19: =IF(AC19="Phase",N(G19),0) -> 0
A20: =IF(A16="","",A16) -> 2370 | B20: =IF(B16="","",B16) -> Tamarack Housing | D20: =IF(COUNTA(C20,E20,H20,I20:O20)=0,"",IF(D16="","",D16)) | F20: =IF(_xlfn.ISFORMULA(G20),"",IF(AND(E20<>"",N(G20)>0),E20+7*G20-1,"")) | G20: =IF(OR(E20="",F20=""),"",IF(F20<E20,"",ROUNDUP((F20-E20+1)/7,0))) | P20: =SUM(I20:O20)*N(G20) -> 0 | Q20: {=IF(OR(A20="",E20="",F20=""),0,SUMPRODUCT((tlNo=A20)*(Timeline!$H$18:$BG$18+6>=E20)*(Timeline!$H$18:$BG$18<=F20)*Timeline!$H$20:$BG$378))} -> 0 | R20: =P20-Q20 -> 0 | S20: =SUMIF($I$3:$O$3,Assumptions!$A$15,$I20:$O20)*N($G20) -> 0 | T20: =SUMIF($I$3:$O$3,Assumptions!$A$16,$I20:$O20)*N($G20) -> 0 | U20: =SUMIF($I$3:$O$3,Assumptions!$A$17,$I20:$O20)*N($G20) -> 0 | V20: =SUMIF($I$3:$O$3,Assumptions!$A$18,$I20:$O20)*N($G20) -> 0 | W20: =SUMIF($I$3:$O$3,Assumptions!$A$19,$I20:$O20)*N($G20) -> 0 | X20: =S20*Assumptions!$B$15+T20*Assumptions!$B$16+U20*Assumptions!$B$17+V20*Assumptions!$B$18+W20*Assumptions!$B$19 -> 0 | Y20: =IF(D20="","",H20-X20) | Z20: =IF(OR(D20="",H20=0),"",X20/H20) | AA20: =IF(D20="Active",1,IF(D20="Prospective",IF(Assumptions!$B$6="Active only",0,Assumptions!$B$7),0)) -> 0 | AB20: =IF(COUNTA(C20,E20,H20,I20:O20)=0,"",IF(C20="","Select phase",IF(OR(E20="",F20=""),"Enter dates",IF(F20<E20,"End before start",IF(H20="","Enter phase fee",IF(P20=0,"Enter staff hours",IF(R20<0,"Over-mapped on Timeline",IF(R20>0,"Map hours on Timeline","OK")))))))) | AC20: Phase | AD20: =IF(AC20="Phase",N(G20),0) -> 0
A21: =IF(A16="","",A16) -> 2370 | B21: =IF(B16="","",B16) -> Tamarack Housing | D21: =IF(COUNTA(C21,E21,H21,I21:O21)=0,"",IF(D16="","",D16)) | F21: =IF(_xlfn.ISFORMULA(G21),"",IF(AND(E21<>"",N(G21)>0),E21+7*G21-1,"")) | G21: =IF(OR(E21="",F21=""),"",IF(F21<E21,"",ROUNDUP((F21-E21+1)/7,0))) | P21: =SUM(I21:O21)*N(G21) -> 0 | Q21: {=IF(OR(A21="",E21="",F21=""),0,SUMPRODUCT((tlNo=A21)*(Timeline!$H$18:$BG$18+6>=E21)*(Timeline!$H$18:$BG$18<=F21)*Timeline!$H$20:$BG$378))} -> 0 | R21: =P21-Q21 -> 0 | S21: =SUMIF($I$3:$O$3,Assumptions!$A$15,$I21:$O21)*N($G21) -> 0 | T21: =SUMIF($I$3:$O$3,Assumptions!$A$16,$I21:$O21)*N($G21) -> 0 | U21: =SUMIF($I$3:$O$3,Assumptions!$A$17,$I21:$O21)*N($G21) -> 0 | V21: =SUMIF($I$3:$O$3,Assumptions!$A$18,$I21:$O21)*N($G21) -> 0 | W21: =SUMIF($I$3:$O$3,Assumptions!$A$19,$I21:$O21)*N($G21) -> 0 | X21: =S21*Assumptions!$B$15+T21*Assumptions!$B$16+U21*Assumptions!$B$17+V21*Assumptions!$B$18+W21*Assumptions!$B$19 -> 0 | Y21: =IF(D21="","",H21-X21) | Z21: =IF(OR(D21="",H21=0),"",X21/H21) | AA21: =IF(D21="Active",1,IF(D21="Prospective",IF(Assumptions!$B$6="Active only",0,Assumptions!$B$7),0)) -> 0 | AB21: =IF(COUNTA(C21,E21,H21,I21:O21)=0,"",IF(C21="","Select phase",IF(OR(E21="",F21=""),"Enter dates",IF(F21<E21,"End before start",IF(H21="","Enter phase fee",IF(P21=0,"Enter staff hours",IF(R21<0,"Over-mapped on Timeline",IF(R21>0,"Map hours on Timeline","OK")))))))) | AC21: Phase | AD21: =IF(AC21="Phase",N(G21),0) -> 0
A22: =IF(A16="","",A16) -> 2370 | B22: =IF(B16="","",B16) -> Tamarack Housing | D22: =IF(COUNTA(C22,E22,H22,I22:O22)=0,"",IF(D16="","",D16)) | F22: =IF(_xlfn.ISFORMULA(G22),"",IF(AND(E22<>"",N(G22)>0),E22+7*G22-1,"")) | G22: =IF(OR(E22="",F22=""),"",IF(F22<E22,"",ROUNDUP((F22-E22+1)/7,0))) | P22: =SUM(I22:O22)*N(G22) -> 0 | Q22: {=IF(OR(A22="",E22="",F22=""),0,SUMPRODUCT((tlNo=A22)*(Timeline!$H$18:$BG$18+6>=E22)*(Timeline!$H$18:$BG$18<=F22)*Timeline!$H$20:$BG$378))} -> 0 | R22: =P22-Q22 -> 0 | S22: =SUMIF($I$3:$O$3,Assumptions!$A$15,$I22:$O22)*N($G22) -> 0 | T22: =SUMIF($I$3:$O$3,Assumptions!$A$16,$I22:$O22)*N($G22) -> 0 | U22: =SUMIF($I$3:$O$3,Assumptions!$A$17,$I22:$O22)*N($G22) -> 0 | V22: =SUMIF($I$3:$O$3,Assumptions!$A$18,$I22:$O22)*N($G22) -> 0 | W22: =SUMIF($I$3:$O$3,Assumptions!$A$19,$I22:$O22)*N($G22) -> 0 | X22: =S22*Assumptions!$B$15+T22*Assumptions!$B$16+U22*Assumptions!$B$17+V22*Assumptions!$B$18+W22*Assumptions!$B$19 -> 0 | Y22: =IF(D22="","",H22-X22) | Z22: =IF(OR(D22="",H22=0),"",X22/H22) | AA22: =IF(D22="Active",1,IF(D22="Prospective",IF(Assumptions!$B$6="Active only",0,Assumptions!$B$7),0)) -> 0 | AB22: =IF(COUNTA(C22,E22,H22,I22:O22)=0,"",IF(C22="","Select phase",IF(OR(E22="",F22=""),"Enter dates",IF(F22<E22,"End before start",IF(H22="","Enter phase fee",IF(P22=0,"Enter staff hours",IF(R22<0,"Over-mapped on Timeline",IF(R22>0,"Map hours on Timeline","OK")))))))) | AC22: Phase | AD22: =IF(AC22="Phase",N(G22),0) -> 0
A23: =IF(A16="","",A16) -> 2370 | B23: =IF(B16="","",B16) -> Tamarack Housing | D23: =IF(COUNTA(C23,E23,H23,I23:O23)=0,"",IF(D16="","",D16)) | F23: =IF(_xlfn.ISFORMULA(G23),"",IF(AND(E23<>"",N(G23)>0),E23+7*G23-1,"")) | G23: =IF(OR(E23="",F23=""),"",IF(F23<E23,"",ROUNDUP((F23-E23+1)/7,0))) | P23: =SUM(I23:O23)*N(G23) -> 0 | Q23: {=IF(OR(A23="",E23="",F23=""),0,SUMPRODUCT((tlNo=A23)*(Timeline!$H$18:$BG$18+6>=E23)*(Timeline!$H$18:$BG$18<=F23)*Timeline!$H$20:$BG$378))} -> 0 | R23: =P23-Q23 -> 0 | S23: =SUMIF($I$3:$O$3,Assumptions!$A$15,$I23:$O23)*N($G23) -> 0 | T23: =SUMIF($I$3:$O$3,Assumptions!$A$16,$I23:$O23)*N($G23) -> 0 | U23: =SUMIF($I$3:$O$3,Assumptions!$A$17,$I23:$O23)*N($G23) -> 0 | V23: =SUMIF($I$3:$O$3,Assumptions!$A$18,$I23:$O23)*N($G23) -> 0 | W23: =SUMIF($I$3:$O$3,Assumptions!$A$19,$I23:$O23)*N($G23) -> 0 | X23: =S23*Assumptions!$B$15+T23*Assumptions!$B$16+U23*Assumptions!$B$17+V23*Assumptions!$B$18+W23*Assumptions!$B$19 -> 0 | Y23: =IF(D23="","",H23-X23) | Z23: =IF(OR(D23="",H23=0),"",X23/H23) | AA23: =IF(D23="Active",1,IF(D23="Prospective",IF(Assumptions!$B$6="Active only",0,Assumptions!$B$7),0)) -> 0 | AB23: =IF(COUNTA(C23,E23,H23,I23:O23)=0,"",IF(C23="","Select phase",IF(OR(E23="",F23=""),"Enter dates",IF(F23<E23,"End before start",IF(H23="","Enter phase fee",IF(P23=0,"Enter staff hours",IF(R23<0,"Over-mapped on Timeline",IF(R23>0,"Map hours on Timeline","OK")))))))) | AC23: Phase | AD23: =IF(AC23="Phase",N(G23),0) -> 0
A24: =IF(A16="","",A16) -> 2370 | B24: =IF(B16="","",B16) -> Tamarack Housing | D24: =IF(COUNTA(C24,E24,H24,I24:O24)=0,"",IF(D16="","",D16)) | F24: =IF(_xlfn.ISFORMULA(G24),"",IF(AND(E24<>"",N(G24)>0),E24+7*G24-1,"")) | G24: =IF(OR(E24="",F24=""),"",IF(F24<E24,"",ROUNDUP((F24-E24+1)/7,0))) | P24: =SUM(I24:O24)*N(G24) -> 0 | Q24: {=IF(OR(A24="",E24="",F24=""),0,SUMPRODUCT((tlNo=A24)*(Timeline!$H$18:$BG$18+6>=E24)*(Timeline!$H$18:$BG$18<=F24)*Timeline!$H$20:$BG$378))} -> 0 | R24: =P24-Q24 -> 0 | S24: =SUMIF($I$3:$O$3,Assumptions!$A$15,$I24:$O24)*N($G24) -> 0 | T24: =SUMIF($I$3:$O$3,Assumptions!$A$16,$I24:$O24)*N($G24) -> 0 | U24: =SUMIF($I$3:$O$3,Assumptions!$A$17,$I24:$O24)*N($G24) -> 0 | V24: =SUMIF($I$3:$O$3,Assumptions!$A$18,$I24:$O24)*N($G24) -> 0 | W24: =SUMIF($I$3:$O$3,Assumptions!$A$19,$I24:$O24)*N($G24) -> 0 | X24: =S24*Assumptions!$B$15+T24*Assumptions!$B$16+U24*Assumptions!$B$17+V24*Assumptions!$B$18+W24*Assumptions!$B$19 -> 0 | Y24: =IF(D24="","",H24-X24) | Z24: =IF(OR(D24="",H24=0),"",X24/H24) | AA24: =IF(D24="Active",1,IF(D24="Prospective",IF(Assumptions!$B$6="Active only",0,Assumptions!$B$7),0)) -> 0 | AB24: =IF(COUNTA(C24,E24,H24,I24:O24)=0,"",IF(C24="","Select phase",IF(OR(E24="",F24=""),"Enter dates",IF(F24<E24,"End before start",IF(H24="","Enter phase fee",IF(P24=0,"Enter staff hours",IF(R24<0,"Over-mapped on Timeline",IF(R24>0,"Map hours on Timeline","OK")))))))) | AC24: Phase | AD24: =IF(AC24="Phase",N(G24),0) -> 0
A25: 2458 | B25: Summit Ridge Village | C25: Project total | D25: Inactive | E25: =IF(COUNT(E26:E33)=0,"",MIN(E26:E33)) | F25: =IF(COUNT(F26:F33)=0,"",MAX(F26:F33)) | H25: =SUM(H26:H33) -> 0 | P25: =SUM(P26:P33) -> 0 | Q25: =SUM(Q26:Q33) -> 0 | R25: =P25-Q25 -> 0 | S25: =SUM(S26:S33) -> 0 | T25: =SUM(T26:T33) -> 0 | U25: =SUM(U26:U33) -> 0 | V25: =SUM(V26:V33) -> 0 | W25: =SUM(W26:W33) -> 0 | X25: =SUM(X26:X33) -> 0 | Y25: =H25-X25 -> 0 | Z25: =IF(H25=0,"",X25/H25) | AB25: =IF(COUNTIF(AB26:AB33,"?*")=0,"No phases yet",IF(COUNTIF(AB26:AB33,"OK")=COUNTIF(AB26:AB33,"?*"),"All OK",(COUNTIF(AB26:AB33,"?*")-COUNTIF(AB26:AB33,"OK"))&" to fix")) -> No phases yet | AC25: Project | AD25: =IF(AC25="Phase",N(G25),0) -> 0
A26: =IF(A25="","",A25) -> 2458 | B26: =IF(B25="","",B25) -> Summit Ridge Village | D26: =IF(COUNTA(C26,E26,H26,I26:O26)=0,"",IF(D25="","",D25)) | F26: =IF(_xlfn.ISFORMULA(G26),"",IF(AND(E26<>"",N(G26)>0),E26+7*G26-1,"")) | G26: =IF(OR(E26="",F26=""),"",IF(F26<E26,"",ROUNDUP((F26-E26+1)/7,0))) | P26: =SUM(I26:O26)*N(G26) -> 0 | Q26: {=IF(OR(A26="",E26="",F26=""),0,SUMPRODUCT((tlNo=A26)*(Timeline!$H$18:$BG$18+6>=E26)*(Timeline!$H$18:$BG$18<=F26)*Timeline!$H$20:$BG$378))} -> 0 | R26: =P26-Q26 -> 0 | S26: =SUMIF($I$3:$O$3,Assumptions!$A$15,$I26:$O26)*N($G26) -> 0 | T26: =SUMIF($I$3:$O$3,Assumptions!$A$16,$I26:$O26)*N($G26) -> 0 | U26: =SUMIF($I$3:$O$3,Assumptions!$A$17,$I26:$O26)*N($G26) -> 0 | V26: =SUMIF($I$3:$O$3,Assumptions!$A$18,$I26:$O26)*N($G26) -> 0 | W26: =SUMIF($I$3:$O$3,Assumptions!$A$19,$I26:$O26)*N($G26) -> 0 | X26: =S26*Assumptions!$B$15+T26*Assumptions!$B$16+U26*Assumptions!$B$17+V26*Assumptions!$B$18+W26*Assumptions!$B$19 -> 0 | Y26: =IF(D26="","",H26-X26) | Z26: =IF(OR(D26="",H26=0),"",X26/H26) | AA26: =IF(D26="Active",1,IF(D26="Prospective",IF(Assumptions!$B$6="Active only",0,Assumptions!$B$7),0)) -> 0 | AB26: =IF(COUNTA(C26,E26,H26,I26:O26)=0,"",IF(C26="","Select phase",IF(OR(E26="",F26=""),"Enter dates",IF(F26<E26,"End before start",IF(H26="","Enter phase fee",IF(P26=0,"Enter staff hours",IF(R26<0,"Over-mapped on Timeline",IF(R26>0,"Map hours on Timeline","OK")))))))) | AC26: Phase | AD26: =IF(AC26="Phase",N(G26),0) -> 0
A27: =IF(A25="","",A25) -> 2458 | B27: =IF(B25="","",B25) -> Summit Ridge Village | D27: =IF(COUNTA(C27,E27,H27,I27:O27)=0,"",IF(D25="","",D25)) | F27: =IF(_xlfn.ISFORMULA(G27),"",IF(AND(E27<>"",N(G27)>0),E27+7*G27-1,"")) | G27: =IF(OR(E27="",F27=""),"",IF(F27<E27,"",ROUNDUP((F27-E27+1)/7,0))) | P27: =SUM(I27:O27)*N(G27) -> 0 | Q27: {=IF(OR(A27="",E27="",F27=""),0,SUMPRODUCT((tlNo=A27)*(Timeline!$H$18:$BG$18+6>=E27)*(Timeline!$H$18:$BG$18<=F27)*Timeline!$H$20:$BG$378))} -> 0 | R27: =P27-Q27 -> 0 | S27: =SUMIF($I$3:$O$3,Assumptions!$A$15,$I27:$O27)*N($G27) -> 0 | T27: =SUMIF($I$3:$O$3,Assumptions!$A$16,$I27:$O27)*N($G27) -> 0 | U27: =SUMIF($I$3:$O$3,Assumptions!$A$17,$I27:$O27)*N($G27) -> 0 | V27: =SUMIF($I$3:$O$3,Assumptions!$A$18,$I27:$O27)*N($G27) -> 0 | W27: =SUMIF($I$3:$O$3,Assumptions!$A$19,$I27:$O27)*N($G27) -> 0 | X27: =S27*Assumptions!$B$15+T27*Assumptions!$B$16+U27*Assumptions!$B$17+V27*Assumptions!$B$18+W27*Assumptions!$B$19 -> 0 | Y27: =IF(D27="","",H27-X27) | Z27: =IF(OR(D27="",H27=0),"",X27/H27) | AA27: =IF(D27="Active",1,IF(D27="Prospective",IF(Assumptions!$B$6="Active only",0,Assumptions!$B$7),0)) -> 0 | AB27: =IF(COUNTA(C27,E27,H27,I27:O27)=0,"",IF(C27="","Select phase",IF(OR(E27="",F27=""),"Enter dates",IF(F27<E27,"End before start",IF(H27="","Enter phase fee",IF(P27=0,"Enter staff hours",IF(R27<0,"Over-mapped on Timeline",IF(R27>0,"Map hours on Timeline","OK")))))))) | AC27: Phase | AD27: =IF(AC27="Phase",N(G27),0) -> 0
A28: =IF(A25="","",A25) -> 2458 | B28: =IF(B25="","",B25) -> Summit Ridge Village | D28: =IF(COUNTA(C28,E28,H28,I28:O28)=0,"",IF(D25="","",D25)) | F28: =IF(_xlfn.ISFORMULA(G28),"",IF(AND(E28<>"",N(G28)>0),E28+7*G28-1,"")) | G28: =IF(OR(E28="",F28=""),"",IF(F28<E28,"",ROUNDUP((F28-E28+1)/7,0))) | P28: =SUM(I28:O28)*N(G28) -> 0 | Q28: {=IF(OR(A28="",E28="",F28=""),0,SUMPRODUCT((tlNo=A28)*(Timeline!$H$18:$BG$18+6>=E28)*(Timeline!$H$18:$BG$18<=F28)*Timeline!$H$20:$BG$378))} -> 0 | R28: =P28-Q28 -> 0 | S28: =SUMIF($I$3:$O$3,Assumptions!$A$15,$I28:$O28)*N($G28) -> 0 | T28: =SUMIF($I$3:$O$3,Assumptions!$A$16,$I28:$O28)*N($G28) -> 0 | U28: =SUMIF($I$3:$O$3,Assumptions!$A$17,$I28:$O28)*N($G28) -> 0 | V28: =SUMIF($I$3:$O$3,Assumptions!$A$18,$I28:$O28)*N($G28) -> 0 | W28: =SUMIF($I$3:$O$3,Assumptions!$A$19,$I28:$O28)*N($G28) -> 0 | X28: =S28*Assumptions!$B$15+T28*Assumptions!$B$16+U28*Assumptions!$B$17+V28*Assumptions!$B$18+W28*Assumptions!$B$19 -> 0 | Y28: =IF(D28="","",H28-X28) | Z28: =IF(OR(D28="",H28=0),"",X28/H28) | AA28: =IF(D28="Active",1,IF(D28="Prospective",IF(Assumptions!$B$6="Active only",0,Assumptions!$B$7),0)) -> 0 | AB28: =IF(COUNTA(C28,E28,H28,I28:O28)=0,"",IF(C28="","Select phase",IF(OR(E28="",F28=""),"Enter dates",IF(F28<E28,"End before start",IF(H28="","Enter phase fee",IF(P28=0,"Enter staff hours",IF(R28<0,"Over-mapped on Timeline",IF(R28>0,"Map hours on Timeline","OK")))))))) | AC28: Phase | AD28: =IF(AC28="Phase",N(G28),0) -> 0
A29: =IF(A25="","",A25) -> 2458 | B29: =IF(B25="","",B25) -> Summit Ridge Village | D29: =IF(COUNTA(C29,E29,H29,I29:O29)=0,"",IF(D25="","",D25)) | F29: =IF(_xlfn.ISFORMULA(G29),"",IF(AND(E29<>"",N(G29)>0),E29+7*G29-1,"")) | G29: =IF(OR(E29="",F29=""),"",IF(F29<E29,"",ROUNDUP((F29-E29+1)/7,0))) | P29: =SUM(I29:O29)*N(G29) -> 0 | Q29: {=IF(OR(A29="",E29="",F29=""),0,SUMPRODUCT((tlNo=A29)*(Timeline!$H$18:$BG$18+6>=E29)*(Timeline!$H$18:$BG$18<=F29)*Timeline!$H$20:$BG$378))} -> 0 | R29: =P29-Q29 -> 0 | S29: =SUMIF($I$3:$O$3,Assumptions!$A$15,$I29:$O29)*N($G29) -> 0 | T29: =SUMIF($I$3:$O$3,Assumptions!$A$16,$I29:$O29)*N($G29) -> 0 | U29: =SUMIF($I$3:$O$3,Assumptions!$A$17,$I29:$O29)*N($G29) -> 0 | V29: =SUMIF($I$3:$O$3,Assumptions!$A$18,$I29:$O29)*N($G29) -> 0 | W29: =SUMIF($I$3:$O$3,Assumptions!$A$19,$I29:$O29)*N($G29) -> 0 | X29: =S29*Assumptions!$B$15+T29*Assumptions!$B$16+U29*Assumptions!$B$17+V29*Assumptions!$B$18+W29*Assumptions!$B$19 -> 0 | Y29: =IF(D29="","",H29-X29) | Z29: =IF(OR(D29="",H29=0),"",X29/H29) | AA29: =IF(D29="Active",1,IF(D29="Prospective",IF(Assumptions!$B$6="Active only",0,Assumptions!$B$7),0)) -> 0 | AB29: =IF(COUNTA(C29,E29,H29,I29:O29)=0,"",IF(C29="","Select phase",IF(OR(E29="",F29=""),"Enter dates",IF(F29<E29,"End before start",IF(H29="","Enter phase fee",IF(P29=0,"Enter staff hours",IF(R29<0,"Over-mapped on Timeline",IF(R29>0,"Map hours on Timeline","OK")))))))) | AC29: Phase | AD29: =IF(AC29="Phase",N(G29),0) -> 0
A30: =IF(A25="","",A25) -> 2458 | B30: =IF(B25="","",B25) -> Summit Ridge Village | D30: =IF(COUNTA(C30,E30,H30,I30:O30)=0,"",IF(D25="","",D25)) | F30: =IF(_xlfn.ISFORMULA(G30),"",IF(AND(E30<>"",N(G30)>0),E30+7*G30-1,"")) | G30: =IF(OR(E30="",F30=""),"",IF(F30<E30,"",ROUNDUP((F30-E30+1)/7,0))) | P30: =SUM(I30:O30)*N(G30) -> 0 | Q30: {=IF(OR(A30="",E30="",F30=""),0,SUMPRODUCT((tlNo=A30)*(Timeline!$H$18:$BG$18+6>=E30)*(Timeline!$H$18:$BG$18<=F30)*Timeline!$H$20:$BG$378))} -> 0 | R30: =P30-Q30 -> 0 | S30: =SUMIF($I$3:$O$3,Assumptions!$A$15,$I30:$O30)*N($G30) -> 0 | T30: =SUMIF($I$3:$O$3,Assumptions!$A$16,$I30:$O30)*N($G30) -> 0 | U30: =SUMIF($I$3:$O$3,Assumptions!$A$17,$I30:$O30)*N($G30) -> 0 | V30: =SUMIF($I$3:$O$3,Assumptions!$A$18,$I30:$O30)*N($G30) -> 0 | W30: =SUMIF($I$3:$O$3,Assumptions!$A$19,$I30:$O30)*N($G30) -> 0 | X30: =S30*Assumptions!$B$15+T30*Assumptions!$B$16+U30*Assumptions!$B$17+V30*Assumptions!$B$18+W30*Assumptions!$B$19 -> 0 | Y30: =IF(D30="","",H30-X30) | Z30: =IF(OR(D30="",H30=0),"",X30/H30) | AA30: =IF(D30="Active",1,IF(D30="Prospective",IF(Assumptions!$B$6="Active only",0,Assumptions!$B$7),0)) -> 0 | AB30: =IF(COUNTA(C30,E30,H30,I30:O30)=0,"",IF(C30="","Select phase",IF(OR(E30="",F30=""),"Enter dates",IF(F30<E30,"End before start",IF(H30="","Enter phase fee",IF(P30=0,"Enter staff hours",IF(R30<0,"Over-mapped on Timeline",IF(R30>0,"Map hours on Timeline","OK")))))))) | AC30: Phase | AD30: =IF(AC30="Phase",N(G30),0) -> 0
A31: =IF(A25="","",A25) -> 2458 | B31: =IF(B25="","",B25) -> Summit Ridge Village | D31: =IF(COUNTA(C31,E31,H31,I31:O31)=0,"",IF(D25="","",D25)) | F31: =IF(_xlfn.ISFORMULA(G31),"",IF(AND(E31<>"",N(G31)>0),E31+7*G31-1,"")) | G31: =IF(OR(E31="",F31=""),"",IF(F31<E31,"",ROUNDUP((F31-E31+1)/7,0))) | P31: =SUM(I31:O31)*N(G31) -> 0 | Q31: {=IF(OR(A31="",E31="",F31=""),0,SUMPRODUCT((tlNo=A31)*(Timeline!$H$18:$BG$18+6>=E31)*(Timeline!$H$18:$BG$18<=F31)*Timeline!$H$20:$BG$378))} -> 0 | R31: =P31-Q31 -> 0 | S31: =SUMIF($I$3:$O$3,Assumptions!$A$15,$I31:$O31)*N($G31) -> 0 | T31: =SUMIF($I$3:$O$3,Assumptions!$A$16,$I31:$O31)*N($G31) -> 0 | U31: =SUMIF($I$3:$O$3,Assumptions!$A$17,$I31:$O31)*N($G31) -> 0 | V31: =SUMIF($I$3:$O$3,Assumptions!$A$18,$I31:$O31)*N($G31) -> 0 | W31: =SUMIF($I$3:$O$3,Assumptions!$A$19,$I31:$O31)*N($G31) -> 0 | X31: =S31*Assumptions!$B$15+T31*Assumptions!$B$16+U31*Assumptions!$B$17+V31*Assumptions!$B$18+W31*Assumptions!$B$19 -> 0 | Y31: =IF(D31="","",H31-X31) | Z31: =IF(OR(D31="",H31=0),"",X31/H31) | AA31: =IF(D31="Active",1,IF(D31="Prospective",IF(Assumptions!$B$6="Active only",0,Assumptions!$B$7),0)) -> 0 | AB31: =IF(COUNTA(C31,E31,H31,I31:O31)=0,"",IF(C31="","Select phase",IF(OR(E31="",F31=""),"Enter dates",IF(F31<E31,"End before start",IF(H31="","Enter phase fee",IF(P31=0,"Enter staff hours",IF(R31<0,"Over-mapped on Timeline",IF(R31>0,"Map hours on Timeline","OK")))))))) | AC31: Phase | AD31: =IF(AC31="Phase",N(G31),0) -> 0
A32: =IF(A25="","",A25) -> 2458 | B32: =IF(B25="","",B25) -> Summit Ridge Village | D32: =IF(COUNTA(C32,E32,H32,I32:O32)=0,"",IF(D25="","",D25)) | F32: =IF(_xlfn.ISFORMULA(G32),"",IF(AND(E32<>"",N(G32)>0),E32+7*G32-1,"")) | G32: =IF(OR(E32="",F32=""),"",IF(F32<E32,"",ROUNDUP((F32-E32+1)/7,0))) | P32: =SUM(I32:O32)*N(G32) -> 0 | Q32: {=IF(OR(A32="",E32="",F32=""),0,SUMPRODUCT((tlNo=A32)*(Timeline!$H$18:$BG$18+6>=E32)*(Timeline!$H$18:$BG$18<=F32)*Timeline!$H$20:$BG$378))} -> 0 | R32: =P32-Q32 -> 0 | S32: =SUMIF($I$3:$O$3,Assumptions!$A$15,$I32:$O32)*N($G32) -> 0 | T32: =SUMIF($I$3:$O$3,Assumptions!$A$16,$I32:$O32)*N($G32) -> 0 | U32: =SUMIF($I$3:$O$3,Assumptions!$A$17,$I32:$O32)*N($G32) -> 0 | V32: =SUMIF($I$3:$O$3,Assumptions!$A$18,$I32:$O32)*N($G32) -> 0 | W32: =SUMIF($I$3:$O$3,Assumptions!$A$19,$I32:$O32)*N($G32) -> 0 | X32: =S32*Assumptions!$B$15+T32*Assumptions!$B$16+U32*Assumptions!$B$17+V32*Assumptions!$B$18+W32*Assumptions!$B$19 -> 0 | Y32: =IF(D32="","",H32-X32) | Z32: =IF(OR(D32="",H32=0),"",X32/H32) | AA32: =IF(D32="Active",1,IF(D32="Prospective",IF(Assumptions!$B$6="Active only",0,Assumptions!$B$7),0)) -> 0 | AB32: =IF(COUNTA(C32,E32,H32,I32:O32)=0,"",IF(C32="","Select phase",IF(OR(E32="",F32=""),"Enter dates",IF(F32<E32,"End before start",IF(H32="","Enter phase fee",IF(P32=0,"Enter staff hours",IF(R32<0,"Over-mapped on Timeline",IF(R32>0,"Map hours on Timeline","OK")))))))) | AC32: Phase | AD32: =IF(AC32="Phase",N(G32),0) -> 0
A33: =IF(A25="","",A25) -> 2458 | B33: =IF(B25="","",B25) -> Summit Ridge Village | D33: =IF(COUNTA(C33,E33,H33,I33:O33)=0,"",IF(D25="","",D25)) | F33: =IF(_xlfn.ISFORMULA(G33),"",IF(AND(E33<>"",N(G33)>0),E33+7*G33-1,"")) | G33: =IF(OR(E33="",F33=""),"",IF(F33<E33,"",ROUNDUP((F33-E33+1)/7,0))) | P33: =SUM(I33:O33)*N(G33) -> 0 | Q33: {=IF(OR(A33="",E33="",F33=""),0,SUMPRODUCT((tlNo=A33)*(Timeline!$H$18:$BG$18+6>=E33)*(Timeline!$H$18:$BG$18<=F33)*Timeline!$H$20:$BG$378))} -> 0 | R33: =P33-Q33 -> 0 | S33: =SUMIF($I$3:$O$3,Assumptions!$A$15,$I33:$O33)*N($G33) -> 0 | T33: =SUMIF($I$3:$O$3,Assumptions!$A$16,$I33:$O33)*N($G33) -> 0 | U33: =SUMIF($I$3:$O$3,Assumptions!$A$17,$I33:$O33)*N($G33) -> 0 | V33: =SUMIF($I$3:$O$3,Assumptions!$A$18,$I33:$O33)*N($G33) -> 0 | W33: =SUMIF($I$3:$O$3,Assumptions!$A$19,$I33:$O33)*N($G33) -> 0 | X33: =S33*Assumptions!$B$15+T33*Assumptions!$B$16+U33*Assumptions!$B$17+V33*Assumptions!$B$18+W33*Assumptions!$B$19 -> 0 | Y33: =IF(D33="","",H33-X33) | Z33: =IF(OR(D33="",H33=0),"",X33/H33) | AA33: =IF(D33="Active",1,IF(D33="Prospective",IF(Assumptions!$B$6="Active only",0,Assumptions!$B$7),0)) -> 0 | AB33: =IF(COUNTA(C33,E33,H33,I33:O33)=0,"",IF(C33="","Select phase",IF(OR(E33="",F33=""),"Enter dates",IF(F33<E33,"End before start",IF(H33="","Enter phase fee",IF(P33=0,"Enter staff hours",IF(R33<0,"Over-mapped on Timeline",IF(R33>0,"Map hours on Timeline","OK")))))))) | AC33: Phase | AD33: =IF(AC33="Phase",N(G33),0) -> 0
A34: 2469 | B34: Fairhaven Village | C34: Project total | D34: Active | E34: =IF(COUNT(E35:E42)=0,"",MIN(E35:E42)) | F34: =IF(COUNT(F35:F42)=0,"",MAX(F35:F42)) | H34: =SUM(H35:H42) -> 0 | P34: =SUM(P35:P42) -> 0 | Q34: =SUM(Q35:Q42) -> 0 | R34: =P34-Q34 -> 0 | S34: =SUM(S35:S42) -> 0 | T34: =SUM(T35:T42) -> 0 | U34: =SUM(U35:U42) -> 0 | V34: =SUM(V35:V42) -> 0 | W34: =SUM(W35:W42) -> 0 | X34: =SUM(X35:X42) -> 0 | Y34: =H34-X34 -> 0 | Z34: =IF(H34=0,"",X34/H34) | AB34: =IF(COUNTIF(AB35:AB42,"?*")=0,"No phases yet",IF(COUNTIF(AB35:AB42,"OK")=COUNTIF(AB35:AB42,"?*"),"All OK",(COUNTIF(AB35:AB42,"?*")-COUNTIF(AB35:AB42,"OK"))&" to fix")) -> No phases yet | AC34: Project | AD34: =IF(AC34="Phase",N(G34),0) -> 0
A35: =IF(A34="","",A34) -> 2469 | B35: =IF(B34="","",B34) -> Fairhaven Village | D35: =IF(COUNTA(C35,E35,H35,I35:O35)=0,"",IF(D34="","",D34)) | F35: =IF(_xlfn.ISFORMULA(G35),"",IF(AND(E35<>"",N(G35)>0),E35+7*G35-1,"")) | G35: =IF(OR(E35="",F35=""),"",IF(F35<E35,"",ROUNDUP((F35-E35+1)/7,0))) | P35: =SUM(I35:O35)*N(G35) -> 0 | Q35: {=IF(OR(A35="",E35="",F35=""),0,SUMPRODUCT((tlNo=A35)*(Timeline!$H$18:$BG$18+6>=E35)*(Timeline!$H$18:$BG$18<=F35)*Timeline!$H$20:$BG$378))} -> 0 | R35: =P35-Q35 -> 0 | S35: =SUMIF($I$3:$O$3,Assumptions!$A$15,$I35:$O35)*N($G35) -> 0 | T35: =SUMIF($I$3:$O$3,Assumptions!$A$16,$I35:$O35)*N($G35) -> 0 | U35: =SUMIF($I$3:$O$3,Assumptions!$A$17,$I35:$O35)*N($G35) -> 0 | V35: =SUMIF($I$3:$O$3,Assumptions!$A$18,$I35:$O35)*N($G35) -> 0 | W35: =SUMIF($I$3:$O$3,Assumptions!$A$19,$I35:$O35)*N($G35) -> 0 | X35: =S35*Assumptions!$B$15+T35*Assumptions!$B$16+U35*Assumptions!$B$17+V35*Assumptions!$B$18+W35*Assumptions!$B$19 -> 0 | Y35: =IF(D35="","",H35-X35) | Z35: =IF(OR(D35="",H35=0),"",X35/H35) | AA35: =IF(D35="Active",1,IF(D35="Prospective",IF(Assumptions!$B$6="Active only",0,Assumptions!$B$7),0)) -> 0 | AB35: =IF(COUNTA(C35,E35,H35,I35:O35)=0,"",IF(C35="","Select phase",IF(OR(E35="",F35=""),"Enter dates",IF(F35<E35,"End before start",IF(H35="","Enter phase fee",IF(P35=0,"Enter staff hours",IF(R35<0,"Over-mapped on Timeline",IF(R35>0,"Map hours on Timeline","OK")))))))) | AC35: Phase | AD35: =IF(AC35="Phase",N(G35),0) -> 0
